{
 "cells": [
  {
   "cell_type": "code",
   "execution_count": 1,
   "metadata": {},
   "outputs": [
    {
     "ename": "RuntimeError",
     "evalue": "asyncio.run() cannot be called from a running event loop",
     "output_type": "error",
     "traceback": [
      "\u001b[0;31m---------------------------------------------------------------------------\u001b[0m",
      "\u001b[0;31mRuntimeError\u001b[0m                              Traceback (most recent call last)",
      "Cell \u001b[0;32mIn[1], line 12\u001b[0m\n\u001b[1;32m      9\u001b[0m     \u001b[38;5;28;01mawait\u001b[39;00m asyncio\u001b[38;5;241m.\u001b[39msleep(\u001b[38;5;241m1\u001b[39m)\n\u001b[1;32m     10\u001b[0m     asyncio\u001b[38;5;241m.\u001b[39mrun(main())  \u001b[38;5;66;03m# Error: Cannot call asyncio.run() from within a running event loop\u001b[39;00m\n\u001b[0;32m---> 12\u001b[0m \u001b[43masyncio\u001b[49m\u001b[38;5;241;43m.\u001b[39;49m\u001b[43mrun\u001b[49m\u001b[43m(\u001b[49m\u001b[43mmain\u001b[49m\u001b[43m(\u001b[49m\u001b[43m)\u001b[49m\u001b[43m)\u001b[49m\n",
      "File \u001b[0;32m/usr/lib/python3.11/asyncio/runners.py:184\u001b[0m, in \u001b[0;36mrun\u001b[0;34m(main, debug)\u001b[0m\n\u001b[1;32m    159\u001b[0m \u001b[38;5;250m\u001b[39m\u001b[38;5;124;03m\"\"\"Execute the coroutine and return the result.\u001b[39;00m\n\u001b[1;32m    160\u001b[0m \n\u001b[1;32m    161\u001b[0m \u001b[38;5;124;03mThis function runs the passed coroutine, taking care of\u001b[39;00m\n\u001b[0;32m   (...)\u001b[0m\n\u001b[1;32m    180\u001b[0m \u001b[38;5;124;03m    asyncio.run(main())\u001b[39;00m\n\u001b[1;32m    181\u001b[0m \u001b[38;5;124;03m\"\"\"\u001b[39;00m\n\u001b[1;32m    182\u001b[0m \u001b[38;5;28;01mif\u001b[39;00m events\u001b[38;5;241m.\u001b[39m_get_running_loop() \u001b[38;5;129;01mis\u001b[39;00m \u001b[38;5;129;01mnot\u001b[39;00m \u001b[38;5;28;01mNone\u001b[39;00m:\n\u001b[1;32m    183\u001b[0m     \u001b[38;5;66;03m# fail fast with short traceback\u001b[39;00m\n\u001b[0;32m--> 184\u001b[0m     \u001b[38;5;28;01mraise\u001b[39;00m \u001b[38;5;167;01mRuntimeError\u001b[39;00m(\n\u001b[1;32m    185\u001b[0m         \u001b[38;5;124m\"\u001b[39m\u001b[38;5;124masyncio.run() cannot be called from a running event loop\u001b[39m\u001b[38;5;124m\"\u001b[39m)\n\u001b[1;32m    187\u001b[0m \u001b[38;5;28;01mwith\u001b[39;00m Runner(debug\u001b[38;5;241m=\u001b[39mdebug) \u001b[38;5;28;01mas\u001b[39;00m runner:\n\u001b[1;32m    188\u001b[0m     \u001b[38;5;28;01mreturn\u001b[39;00m runner\u001b[38;5;241m.\u001b[39mrun(main)\n",
      "\u001b[0;31mRuntimeError\u001b[0m: asyncio.run() cannot be called from a running event loop"
     ]
    }
   ],
   "source": [
    "import asyncio\n",
    "\n",
    "async def nested_coroutine():\n",
    "    print(\"Running nested coroutine...\")\n",
    "\n",
    "async def main():\n",
    "    loop = asyncio.get_event_loop()\n",
    "    loop.create_task(nested_coroutine())\n",
    "    await asyncio.sleep(1)\n",
    "    asyncio.run(main())  # Error: Cannot call asyncio.run() from within a running event loop\n",
    "\n",
    "asyncio.run(main())"
   ]
  }
 ],
 "metadata": {
  "kernelspec": {
   "display_name": "Python 3 (ipykernel)",
   "language": "python",
   "name": "python3"
  }
 },
 "nbformat": 4,
 "nbformat_minor": 2
}
